<sdf version='1.6'>
  <model name='kmr'>
    <link name='base_footprint'/>

    <joint name="fixed" type="fixed">
        <parent>base_footprint</parent>
        <child>base_link</child>
    </joint>

    <link name='base_link'>
      <collision name='base_link_collision'>
        <pose frame=''>0 0 -0.1885 0 -0 0</pose>
        <geometry>
          <box>
            <size>1.08 0.63 0.085</size>
          </box>
        </geometry>
      </collision>
      <visual name='base_link_visual'>
        <pose frame=''>0 0 -0.1885 0 -0 0</pose>
        <geometry>
          <box>
            <size>1.08 0.63 0.085</size>
          </box>
        </geometry>
      </visual>
    </link>

    <joint name="base_bottom_to_middle_joint" type="fixed">
      <child>base_link_middle</child>
      <parent>base_link</parent>
    </joint>

    <link name="base_link_middle">
      <collision name='base_link_middle_collision'>
        <pose frame=''>0 0 -0.122 0 -0 0</pose>
        <geometry>
          <box>
            <size>0.92 0.51 0.055</size>
          </box>
        </geometry>
      </collision>
      <visual name='base_link_middle_visual'>
        <pose frame=''>0 0 -0.122 0 -0 0</pose>
        <geometry>
          <box>
            <size>0.84 0.48 0.048</size>
          </box>
        </geometry>
      </visual>
    </link>

    <joint name="base_middle_to_top_joint" type="fixed">
      <child>base_link_top</child>
      <parent>base_link_middle</parent>
    </joint>

    <link name="base_link_top">
      <visual name='base_link_top_visual'>
        <pose frame=''>0 0 0.1645 0 -0 0</pose>
        <geometry>
          <box>
            <size>1.08 0.63 0.525</size>
          </box>
        </geometry>
      </visual>
      <collision name='base_link_top_collision'>
        <pose frame=''>0 0 0.1645 0 -0 0</pose>
        <geometry>
          <box>
            <size>1.08 0.63 0.525</size>
          </box>
        </geometry>
      </collision>
    </link>

    <joint name="back_left_wheel_joint" type="revolute">
        <parent> base_link</parent>
        <child>back_left_wheel_link</child>
        <pose>-0.28 0.1825 -0.135</pose>
        <axis>
            <xyz>0 1 0</xyz>
        </axis>
    </joint>


    <link name="back_left_wheel_link">
      <visual name='back_left_wheel_link_visual'>
        <pose frame=''>-0.28 0.1825 -0.135 0 -0 0</pose>
        <geometry>
          <mesh>
            <scale>1 1 1</scale>
            <uri>model://kmr/meshes/wheels/omni_wheel_1.dae</uri>
          </mesh>
        </geometry>
      </visual>
      <collision name='back_left_wheel_link_collision'>
        <pose frame=''>-0.28 0.1825 -0.135 1.570796 -0 0</pose>
        <geometry>
          <cylinder>
            <length>0.100</length>
            <radius>0.125</radius>
          </cylinder>
        </geometry>
      </collision>

    </link>

    <joint name="back_right_wheel_joint" type="revolute">
        <parent>base_link</parent>
        <child>back_right_wheel_link</child>
        <pose>-0.28 -0.1825 -0.135</pose>
        <axis>
            <xyz>0 1 0</xyz>
        </axis>
    </joint>


    <link name="back_right_wheel_link">
      <visual name='back_right_wheel_link_visual'>
        <pose frame=''>-0.28 -0.1825 -0.135 0 -0 0</pose>
        <geometry>
          <mesh>
            <scale>1 1 1</scale>
            <uri>model://kmr/meshes/wheels/omni_wheel_1.dae</uri>
          </mesh>
        </geometry>
      </visual>
      <collision name='back_right_wheel_link_collision'>
        <pose frame=''>-0.28 -0.1825 -0.135 1.570796 -0 0</pose>
        <geometry>
          <cylinder>
            <length>0.100</length>
            <radius>0.125</radius>
          </cylinder>
        </geometry>
      </collision>
    </link>

   <joint name="front_left_wheel_joint" type="revolute">
        <parent>base_link</parent>
        <child>front_left_wheel_link</child>
        <pose>0.28 0.1825 -0.135</pose>
        <axis>
            <xyz>0 1 0</xyz>
        </axis>
   </joint>

    <link name="front_left_wheel_link">
        <collision name='front_left_wheel_link_collision'>
            <pose frame=''>0.28 0.1825 -0.135 1.570796 -0 0</pose>
            <geometry>
              <cylinder>
                <length>0.100</length>
                <radius>0.125</radius>
              </cylinder>
            </geometry>
        </collision>
        <visual name='front_left_wheel_link_visual'>
            <pose frame=''>0.28 0.1825 -0.135 0 -0 0</pose>
            <geometry>
              <mesh>
                <scale>1 1 1</scale>
                <uri>model://kmr/meshes/wheels/omni_wheel_1.dae</uri>
              </mesh>
            </geometry>
        </visual>
    </link>

    <joint name="front_right_wheel_joint" type="revolute">
        <parent>base_link</parent>
        <child>front_right_wheel_link</child>
        <pose>0.28 -0.1825 -0.135</pose>
        <axis>
            <xyz>0 1 0</xyz>
        </axis>
    </joint>


    <link name="front_right_wheel_link">
       <collision name='front_right_wheel_link_collision'>
        <pose frame=''>0.28 -0.1825 -0.135 1.570796 -0 0</pose>
        <geometry>
          <cylinder>
            <length>0.100</length>
            <radius>0.125</radius>
          </cylinder>
        </geometry>
       </collision>
       <visual name='front_right_wheel_link_visual'>
            <pose frame=''>0.28 -0.1825 -0.135 0 -0 0</pose>
            <geometry>
              <mesh>
                <scale>1 1 1</scale>
                <uri>model://kmr/meshes/wheels/omni_wheel_1.dae</uri>
              </mesh>
            </geometry>
       </visual>
    </link>
    <joint name="laser_B1_joint" type="fixed">
        <parent>base_link</parent>
        <child>laser_B1_link</child>
        <pose>0.483 -0.258 -0.112 3.1413 -0 -0.7854</pose>
    </joint>

    <joint name="laser_B1_joint2" type="fixed">
        <parent>base_link_top</parent>
        <child>laser_B1_link</child>
    </joint>

    <link name='laser_B1_link'>
      <visual name='laser_B1_link_visual'>
        <pose frame=''>0.483 -0.258 -0.112 3.1413 -0 -0.7854</pose>
        <geometry>
          <mesh>
            <scale>1 1 1</scale>
            <uri>model://kmr/meshes/sensors/visual/sick_lms1xx.dae</uri>
          </mesh>
        </geometry>
      </visual>
      <collision name='laser_B1_link_collision'>
        <pose frame=''>0.483 -0.258 -0.112 3.1413 0 -0.7854</pose>
        <geometry>
          <mesh>
            <scale>1 1 1</scale>
            <uri>model://kmr/meshes/sensors/collision/sick_lms1xx.stl</uri>
          </mesh>
        </geometry>
      </collision>
      <sensor name="sensor_B1" type="ray">
        <always_on>true</always_on>
        <visualize>true</visualize>
        <pose frame=''>0.483 -0.258 -0.112 0 -0 -0.7854</pose>
        <update_rate>5</update_rate>
        <ray>
          <scan>
            <horizontal>
              <samples>540</samples>
              <resolution>1.000000</resolution>
              <min_angle>-1.5708</min_angle>
              <max_angle>1.5708</max_angle>
            </horizontal>
          </scan>
          <range>
            <min>0.3</min>
            <max>10</max>
            <resolution>0.015000</resolution>
          </range>
          <noise>
            <type>gaussian</type>
            <mean>0.0</mean>
            <stddev>0.01</stddev>
          </noise>
        </ray>
        <plugin name="gazebo_sensor_B1_controller" filename="libgazebo_ros_ray_sensor.so">
          <ros>
            <argument>~/out:=scan</argument>
          </ros>
          <output_type>sensor_msgs/LaserScan</output_type>
          <frame_name>laser_B1_link</frame_name>
        </plugin>
      </sensor>
    </link>

    <joint name="laser_B4_joint" type="fixed">
        <parent>base_link</parent>
        <child>laser_B4_link</child>
        <pose>-0.483 0.258 -0.112 0 3.1413 5.4977</pose>
    </joint>

    <joint name="laser_B4_joint2" type="fixed">
        <parent>base_link_top</parent>
        <child>laser_B4_link</child>
    </joint>


    <link name='laser_B4_link'>
      <collision name='laser_B4_link_collision'>
        <pose frame=''>-0.483 0.258 -0.112 0 3.1413 5.4977</pose>
        <geometry>
          <mesh>
            <scale>1 1 1</scale>
            <uri>model://kmr/meshes/sensors/collision/sick_lms1xx.stl</uri>
          </mesh>
        </geometry>
      </collision>
      <visual name='laser_B4_link_visual'>
        <pose frame=''>-0.483 0.258 -0.112 0 3.1413 5.4977</pose>
        <geometry>
          <mesh>
            <scale>1 1 1</scale>
            <uri>model://kmr/meshes/sensors/visual/sick_lms1xx.dae</uri>
          </mesh>
        </geometry>
      </visual>
      <sensor name="sensor_B4" type="ray">
        <always_on>true</always_on>
        <visualize>true</visualize>
        <pose frame=''>-0.483 0.258 -0.112 3.1413 3.1413 5.4977</pose>
        <update_rate>5</update_rate>
        <ray>
          <scan>
            <horizontal>
              <samples>540</samples>
              <resolution>1.000000</resolution>
              <min_angle>-1.5708</min_angle>
              <max_angle>1.5708</max_angle>
            </horizontal>
          </scan>
          <range>
            <min>0.3</min>
            <max>10</max>
            <resolution>0.015000</resolution>
          </range>
          <noise>
            <type>gaussian</type>
            <mean>0.0</mean>
            <stddev>0.01</stddev>
          </noise>
        </ray>
        <plugin name="gazebo_sensor_B4_controller" filename="libgazebo_ros_ray_sensor.so">
          <ros>
            <argument>~/out:=scan_2</argument>
          </ros>
          <output_type>sensor_msgs/LaserScan</output_type>
          <frame_name>laser_B4_link</frame_name>
        </plugin>
      </sensor>
    </link>

    <joint name="base_iiwa_joint" type="fixed">
        <parent>base_link_top</parent>
        <child>base_iiwa</child>
        <pose>0.363 -0.184 0.427 0 0 -1.5708</pose>
    </joint>

    <link name="base_iiwa">
         <visual name='base_iiwa_visual'>
            <pose frame=''>0.363 -0.184 0.427 0 0 -1.5708</pose>
            <geometry>
              <mesh>
                <scale>1 1 1</scale>
                <uri>model://kmr/meshes/lbr_iiwa_14_r820/visual/base_link.dae</uri>
              </mesh>
            </geometry>
         </visual>
         <collision name='base_iiwa_collision'>
            <pose frame=''>0.363 -0.184 0.427 0 0 -1.5708</pose>
            <geometry>
              <mesh>
                <scale>1 1 1</scale>
                <uri>model://kmr/meshes/lbr_iiwa_14_r820/collision/base_link.stl</uri>
              </mesh>
            </geometry>
         </collision>
    </link>

    <joint name="joint_a1" type="fixed">
        <parent>base_iiwa</parent>
        <child>link_1</child>
        <pose>0.363 -0.184 0.427 0 0 -1.5708</pose>
        <axis>
            <xyz>0 0 1</xyz>
        </axis>
    </joint>


    <link name="link_1">
          <collision name='link_1_collision'>
            <pose frame=''>0.363 -0.184 0.427 0 0 -1.5708</pose>
            <geometry>
              <mesh>
                <scale>1 1 1</scale>
                <uri>model://kmr/meshes/lbr_iiwa_14_r820/collision/link_1.stl</uri>
              </mesh>
            </geometry>
          </collision>

          <visual name='link_1_visual'>
            <pose frame=''>0.363 -0.184 0.427 0 0 -1.5708</pose>
            <geometry>
              <mesh>
                <scale>1 1 1</scale>
                <uri>model://kmr/meshes/lbr_iiwa_14_r820/visual/link_1.dae</uri>
              </mesh>
            </geometry>
          </visual>
    </link>

    <joint name="joint_a2" type="fixed">
        <parent>link_1</parent>
        <child>link_2</child>
        <pose>0.363 -0.183564 0.787 0 0 -1.5708</pose>
        <axis>
            <xyz>0 1 0</xyz>
        </axis>
    </joint>

    <link name="link_2">
      <collision name='link_2_collision'>
        <pose frame=''>0.363 -0.183564 0.787 0 0 -1.5708</pose>
        <geometry>
          <mesh>
            <scale>1 1 1</scale>
            <uri>model://kmr/meshes/lbr_iiwa_14_r820/collision/link_2.stl</uri>
          </mesh>
        </geometry>
      </collision>
      <visual name='link_2_visual'>
        <pose frame=''>0.363 -0.183564 0.787 0 0 -1.5708</pose>
        <geometry>
          <mesh>
            <scale>1 1 1</scale>
            <uri>model://kmr/meshes/lbr_iiwa_14_r820/visual/link_2.dae</uri>
          </mesh>
        </geometry>
      </visual>
    </link>

    <joint name="joint_a3" type="fixed">
        <parent>link_2</parent>
        <child>link_3</child>
        <pose>0.363 -0.183564 0.787 0 0 -1.5708</pose>
        <axis>
            <xyz>0 0 1</xyz>
        </axis>
    </joint>


    <link name="link_3">
      <visual name='link_3_visual'>
        <pose frame=''>0.363 -0.183564 0.787 0 0 -1.5708</pose>
        <geometry>
          <mesh>
            <scale>1 1 1</scale>
            <uri>model://kmr/meshes/lbr_iiwa_14_r820/visual/link_3.dae</uri>
          </mesh>
        </geometry>
      </visual>
      <collision name='link_3_collision'>
        <pose frame=''>0.363 -0.183564 0.787 0 0 -1.5708</pose>
        <geometry>
          <mesh>
            <scale>1 1 1</scale>
            <uri>model://kmr/meshes/lbr_iiwa_14_r820/collision/link_3.stl</uri>
          </mesh>
        </geometry>
      </collision>
    </link>

    <joint name="joint_a4" type="fixed">
        <parent>link_3</parent>
        <child>link_4</child>
        <pose>0.363 -0.184 1.207 0 0 -1.5708</pose>
        <axis>
            <xyz>0 -1 0</xyz>
        </axis>
    </joint>

    <link name="link_4">
      <collision name='link_4_collision'>
        <pose frame=''>0.363 -0.184 1.207 0 0 -1.5708</pose>
        <geometry>
          <mesh>
            <scale>1 1 1</scale>
            <uri>model://kmr/meshes/lbr_iiwa_14_r820/collision/link_4.stl</uri>
          </mesh>
        </geometry>
      </collision>
      <visual name='link_4_visual'>
        <pose frame=''>0.363 -0.184 1.207 0 0 -1.5708</pose>
        <geometry>
          <mesh>
            <scale>1 1 1</scale>
            <uri>model://kmr/meshes/lbr_iiwa_14_r820/visual/link_4.dae</uri>
          </mesh>
        </geometry>
      </visual>
    </link>

    <joint name="joint_a5" type="fixed">
        <parent>link_4</parent>
        <child>link_5</child>
        <pose>0.363 -0.184 1.207 0 0 -1.5708</pose>
        <axis>
            <xyz>0 0 1</xyz>
        </axis>
    </joint>

    <link name="link_5">
      <collision name='link_5_collision'>
        <pose frame=''>
            0.363 -0.184 1.207 0 0 -1.5708
        </pose>
        <geometry>
          <mesh>
            <scale>1 1 1</scale>
            <uri>model://kmr/meshes/lbr_iiwa_14_r820/collision/link_5.stl</uri>
          </mesh>
        </geometry>
      </collision>
      <visual name='link_5_visual'>
        <pose frame=''>0.363 -0.184 1.207 0 0 -1.5708</pose>
        <geometry>
          <mesh>
            <scale>1 1 1</scale>
            <uri>model://kmr/meshes/lbr_iiwa_14_r820/visual/link_5.dae</uri>
          </mesh>
        </geometry>
      </visual>
    </link>

    <joint name="joint_a6" type="fixed">
        <parent>link_5</parent>
        <child>link_6</child>
        <pose>0.363 -0.184 1.607 0 0 -1.5708</pose>
        <axis>
            <xyz>0 1 0</xyz>
        </axis>
    </joint>

    <link name="link_6">
      <collision name='link_6_collision'>
        <pose frame=''>0.363 -0.184 1.607 0 0 -1.5708</pose>
        <geometry>
          <mesh>
            <scale>1 1 1</scale>
            <uri>model://kmr/meshes/lbr_iiwa_14_r820/collision/link_6.stl</uri>
          </mesh>
        </geometry>
      </collision>
      <visual name='link_6_visual'>
        <pose frame=''>0.363 -0.184 1.607 0 0 -1.5708</pose>
        <geometry>
          <mesh>
            <scale>1 1 1</scale>
            <uri>model://kmr/meshes/lbr_iiwa_14_r820/visual/link_6.dae</uri>
          </mesh>
        </geometry>
      </visual>
    </link>

    <joint name="joint_a7" type="fixed">
        <parent>link_6</parent>
        <child>link_7</child>
        <pose>0.363 -0.184 1.607 0 0 -1.5708</pose>
        <axis>
            <xyz>0 0 1</xyz>
        </axis>
    </joint>

    <link name="link_7">
      <collision name='link_7_collision'>
        <pose frame=''>0.363 -0.184 1.607 0 0 -1.5708</pose>
        <geometry>
          <mesh>
            <scale>1 1 1</scale>
            <uri>model://kmr/meshes/lbr_iiwa_14_r820/collision/link_7.stl</uri>
          </mesh>
        </geometry>
      </collision>
      <visual name='link_7_visual'>
        <pose frame=''>0.363 -0.184 1.607 0 0 -1.5708</pose>
        <geometry>
          <mesh>
            <scale>1 1 1</scale>
            <uri>model://kmr/meshes/lbr_iiwa_14_r820/visual/link_7.dae</uri>
          </mesh>
        </geometry>
      </visual>
    </link>

    <joint name="joint_tool0" type="fixed">
        <parent>link_7</parent>
        <child>tool0</child>
        <axis>
            <xyz>0 0 0</xyz>
        </axis>
    </joint>

    <link name="tool0"/>

  

    <!-- camera depth joints and links -->


    <joint name="d435_base_front_joint" type="fixed">
        <parent>base_link_top</parent>
        <child>d435_base_front_link</child>
        <pose>0.486 0.065 0.436 1.570796 0 1.570796</pose>
        <axis>
            <xyz>0 0 0</xyz>
        </axis>
    </joint> 

    <link name="d435_base_front_link">
      <collision name='d435_link_collision'>
        <pose frame=''>0.486 0.065 0.436 1.570796 0 1.570796</pose>
        <geometry>
          <box>
            <size>0.02505 0.090 0.025</size>
          </box>
        </geometry>
      </collision>
    </link>

     <joint name="d435_base_front_depth_joint" type="fixed">
      <pose>0.02 -0.0075 0.9 0 0 0 </pose>
      <parent> d435_base_front_link </parent>
      <child> d435_base_front_depth_frame </child>
    </joint>
    <link name="d435_base_front_depth_frame"/>


    <joint name="d435_base_front_depth_optical_joint" type="fixed">
      <pose>0 0 0 -1.570796 0 -1.570796 </pose>
      <parent>d435_base_front_depth_frame </parent>
      <child> d435_base_front_depth_optical_frame_link</child>
    </joint>

    <link name="d435_base_front_depth_optical_frame_link">
      <pose>0.02 -0.0075 0.9 0 0 0 </pose>
      <sensor name="camera" type="depth">
        <always_on>true</always_on>
        <visualize>true</visualize>
        <pose frame=''>0.02 -0.0075 0.9 0 -0 0</pose>
        <update_rate>30</update_rate>
        <camera name="intel_realsense_d435">
          <horizontal_fov>1.02974</horizontal_fov>
          <image>
              <width>640</width>
              <height>480</height>
              <format>B8G8R8</format>
          </image>
          <depth_camera>
            <output>depths</output>
          </depth_camera>
          <clip>
              <near>0.01</near>
              <far>300</far>
          </clip>
          <noise>
            <type>gaussian</type>
            <!-- Noise is sampled independently per pixel on each frame.
                  That pixel's noise value is added to each of its color
                  channels, which at that point lie in the range [0,1]. -->
            <mean>0.0</mean>
            <stddev>0.007</stddev>
          </noise>
        </camera>
          <plugin name="camera_driver" filename="libgazebo_ros_camera.so">
            <ros>
              <!-- topics need to be prefixed with camera_name for remapping -->
              <remapping>mycamera/image_raw:=mycamera/image_demo</remapping>
              <remapping>mycamera/depth/image_raw:=mycamera/depth_demo</remapping>
              <remapping>mycamera/camera_info:=mycamera/image_demo/camera_info</remapping>
              <remapping>mycamera/depth/camera_info:=mycamera/depth_demo/camera_info</remapping>
              <remapping>mycamera/points:=points2</remapping>
            </ros>

            <!-- omit camera_name to default to sensor name -->
            <camera_name>mycamera</camera_name>

            <!-- camera_name>omit so it defaults to sensor name</camera_name-->
            <!-- frame_name>omit so it defaults to link name</frameName-->
            <!-- <hack_baseline>0.07</hack_baseline> -->
          </plugin>
      </sensor>
    </link>

    


    

    <plugin name='planar_move' filename='libgazebo_ros_planar_move.so'>
        <ros>
          <argument>cmd_vel:=cmd_vel</argument>
          <argument>odom:=odom</argument>
        </ros>

        <update_rate>100</update_rate>
        <publish_rate>10</publish_rate>

        <!-- output -->
        <publish_odom>true</publish_odom>
        <publish_odom_tf>true</publish_odom_tf>

        <odometry_frame>odom</odometry_frame>
        <robot_base_frame>base_footprint</robot_base_frame>

        <covariance_x>0.0001</covariance_x>
        <covariance_y>0.0001</covariance_y>
        <covariance_yaw>0.01</covariance_yaw>
    </plugin>

    <plugin name="gazebo_ros_joint_state_publisher" filename="libgazebo_ros_joint_state_publisher.so">
      <ros>
        <!-- <namespace>/tb3</namespace> -->
        <argument>~/out:=joint_states</argument>
      </ros>
      <update_rate>30</update_rate>
      <joint_name>back_right_wheel_joint</joint_name>
      <joint_name>back_left_wheel_joint</joint_name>
      <joint_name>front_left_wheel_joint</joint_name>
      <joint_name>front_right_wheel_joint</joint_name>
    </plugin>
  </model>
</sdf>
