<?xml version="1.0"?>
<robot name="kmr" xmlns:xacro="http://ros.org/wiki/xacro">

  <link name="base_footprint"/>

  <joint name="bf" type="fixed">
      <parent link="base_footprint"/>
      <child link="base_link"/>
      <origin rpy="0 0 0.0" xyz="0 0 0.0775"/>
  </joint>

  <material name="Orange">
    <color rgba="1.0 0.4 0.0 1.0"/>
  </material>
  <material name="Grey">
    <color rgba="0.7 0.7 0.7 1.0"/>
  </material>
  <material name="DarkGrey">
    <color rgba="0.3 0.3 0.3 1.0"/>
  </material>
  <material name="White">
    <color rgba="1.0 1.0 1.0 1.0"/>
  </material>
  <material name="Black">
    <color rgba="0.0 0.0 0.0 1.0"/>
  </material>
  <material name="Red">
    <color rgba="1.0 0.0 0.0 1.0"/>
  </material>
  <material name="Green">
    <color rgba="0.0 1.0 0.0 1.0"/>
  </material>
  <material name="aluminum">
    <color rgba="0.5 0.5 0.5 1"/>
  </material>

  <link name="base_link">
      <visual>
        <geometry>
          <box size="1.08 0.63 0.085"/>
        </geometry>
        <origin rpy="0 0 0" xyz="0 0 0"/>
        <material name="Orange"/>
      </visual>
      <collision>
        <geometry>
          <box size="1.08 0.63 0.085"/>
        </geometry>
      </collision>
      <inertial>
          <mass value="55.04"/>
          <inertia ixx="5.383" ixy="0.0" ixz="0.0" iyy="7.170" iyz="0.0" izz="1.854"/>
        </inertial>
  </link>

  <joint name="base_bottom_to_middle_joint" type="fixed">
          <parent link="base_link" />
          <child link="base_link_middle" />
          <origin xyz="0 0 0.0665" rpy="0 0 0"/>
  </joint>

  <link name="base_link_middle">
      <visual>
        <geometry>
          <box size="0.84 0.48 0.048"/>
        </geometry>
        <origin rpy="0 0 0" xyz="0 0 0.0"/>
        <material name="Orange"/>
      </visual>
      <collision>
        <geometry>
          <box size="0.920 0.51 0.055"/>
        </geometry>
      </collision>
      <inertial>
          <mass value="18.42"/>
          <inertia ixx="1.0866" ixy="0.0" ixz="0.0" iyy="1.437" iyz="0.0" izz="0.357"/>
      </inertial>
    </link>

  <joint name="base_middle_to_top_joint" type="fixed">
          <parent link="base_link_middle" />
          <child link="base_link_top" />
          <origin xyz="0 0 0.2865" rpy="0 0 0"/>
  </joint>

  <link name="base_link_top">
      <visual>
        <geometry>
          <box size="1.08 0.63 0.525"/>
        </geometry>
        <origin rpy="0 0 0" xyz="0 0 0.0"/>
        <material name="Grey"/>
      </visual>
      <collision>
        <geometry>
          <box size="1.08 0.63 0.5335"/>
        </geometry>
      </collision>
      <inertial>
          <mass value="339.96"/>
          <inertia ixx="39.1077" ixy="0.0" ixz="0.0" iyy="42.397" iyz="0.0" izz="18.238"/>
      </inertial>
  </link>




  <joint name="laser_B1_joint" type="fixed">
          <parent link="base_link" />
          <child link="laser_B1_link" />
          <origin xyz="0.483 -0.258 0.0765" rpy="0 0 -0.7854"/>
  </joint>

  <link name="laser_B1_link">
      <visual>
        <origin xyz="0 0 0" rpy="3.1413 0 0"/>
        <geometry>
            <mesh filename="package://kmr_bringup/meshes/sensors/visual/sick_lms1xx.dae" />
        </geometry>
        <material name="dark"/>
      </visual>
      <collision>
          <origin xyz="0.0 0 0.0" rpy="0 0 0"/>
          <geometry>
              <mesh filename="package://kmr_bringup/meshes/sensors/collision/sick_lms1xx.stl" />
          </geometry>
      </collision>
      <inertial>
          <mass value="1.2"/>
          <inertia ixx="0.002355" ixy="0.0" ixz="0.0" iyy="0.002355" iyz="0.0" izz="0.0002809"/>
      </inertial>
  </link>

  <joint name="laser_B4_joint" type="fixed">
          <parent link="base_link" />
          <child link="laser_B4_link" />
          <origin xyz="-0.483 0.258 0.0765" rpy="0 0 2.3562"/>
  </joint>

  <link name="laser_B4_link">
      <visual>
        <origin xyz="0.0 0 0" rpy="0 3.1413 3.1413"/>
        <geometry>
            <mesh filename="package://kmr_bringup/meshes/sensors/visual/sick_lms1xx.dae" />
        </geometry>
        <material name="dark"/>
      </visual>
      <collision>
          <origin xyz="0 0 0" rpy="0 0 0"/>
          <geometry>
                <mesh filename="package://kmr_bringup/meshes/sensors/collision/sick_lms1xx.stl" />
          </geometry>
      </collision>
      <inertial>
          <mass value="1.2"/>
          <inertia ixx="0.002355" ixy="0.0" ixz="0.0" iyy="0.002355" iyz="0.0" izz="0.0002809"/>
      </inertial>
  </link>

  <link name="front_left_wheel_link">
      <visual>
        <origin xyz="0 0 0" rpy="0 0 0" />
        <geometry>
          <mesh filename="package://kmr_bringup/meshes/wheels/omni_wheel_1.dae" />
        </geometry>
      </visual>
      <collision>
        <geometry>
          <cylinder length="0.175" radius="0.125" />
        </geometry>
      </collision>

      <inertial>
        <mass value="6.5" />
        <origin xyz="0 0 0" />
        <inertia ixx="0.04197" ixy="0.0" ixz="0.0" iyy="0.0508" iyz="0.0" izz="0.04197"/>
      </inertial>
  </link>

  <link name="front_right_wheel_link">
      <visual>
        <origin xyz="0 0 0" rpy="0 0 0" />
        <geometry>
          <mesh filename="package://kmr_bringup/meshes/wheels/omni_wheel_1.dae" />
        </geometry>
      </visual>
      <collision>
        <geometry>
          <cylinder length="0.175" radius="0.125" />
        </geometry>
      </collision>

      <inertial>
        <mass value="6.5" />
        <origin xyz="0 0 0" />
        <inertia ixx="0.04197" ixy="0.0" ixz="0.0" iyy="0.0508" iyz="0.0" izz="0.04197"/>
      </inertial>
  </link>

  <link name="back_left_wheel_link">
      <visual>
        <origin xyz="0 0 0" rpy="0 0 0" />
        <geometry>
          <mesh filename="package://kmr_bringup/meshes/wheels/omni_wheel_1.dae" />
        </geometry>
      </visual>
      <collision>
        <geometry>
          <cylinder length="0.175" radius="0.125" />
        </geometry>
      </collision>

      <inertial>
        <mass value="6.5" />
        <origin xyz="0 0 0" />
        <inertia ixx="0.04197" ixy="0.0" ixz="0.0" iyy="0.0508" iyz="0.0" izz="0.04197"/>
      </inertial>
  </link>

  <link name="back_right_wheel_link">
      <visual>
        <origin xyz="0 0 0" rpy="0 0 0" />
        <geometry>
          <mesh filename="package://kmr_bringup/meshes/wheels/omni_wheel_1.dae" />
        </geometry>
      </visual>
      <collision>
        <geometry>
          <cylinder length="0.175" radius="0.125" />
        </geometry>
      </collision>
      <inertial>
        <mass value="6.5" />
        <origin xyz="0 0 0" />
        <inertia ixx="0.04197" ixy="0.0" ixz="0.0" iyy="0.0508" iyz="0.0" izz="0.04197"/>
      </inertial>
  </link>

  <joint name="front_left_wheel_joint" type="fixed">
      <parent link="base_link"/>
      <child link="front_left_wheel_link"/>
      <axis xyz="0 1 0"/>
      <origin xyz="0.28 0.1825 0.0535"/>
      <limit effort="100" velocity="100"/>
      <joint_properties damping="0.0" friction="0.0"/>
  </joint>

  <joint name="front_right_wheel_joint" type="fixed">
      <parent link="base_link"/>
      <child link="front_right_wheel_link"/>
      <origin xyz="0.28 -0.1825 0.0535"/>
      <axis xyz="0 1 0"/>
      <limit effort="100" velocity="100"/>
      <joint_properties damping="0.0" friction="0.0"/>
  </joint>

  <joint name="back_left_wheel_joint" type="fixed">
      <parent link="base_link"/>
      <child link="back_left_wheel_link"/>
      <origin xyz="-0.28 0.1825 0.0535"/>
      <axis xyz="0 1 0"/>
      <limit effort="100" velocity="100"/>
      <joint_properties damping="0.0" friction="0.0"/>
  </joint>

  <joint name="back_right_wheel_joint" type="fixed">
      <parent link="base_link"/>
      <child link="back_right_wheel_link"/>
      <origin xyz="-0.28 -0.1825 0.0535"/>
      <axis xyz="0 1 0"/>
      <limit effort="100" velocity="100"/>
      <joint_properties damping="0.0" friction="0.0"/>
  </joint>

      <joint name="base_link-to-iiwa" type="fixed">
      <origin rpy="0 0 -1.5708" xyz="0.363 -0.184 0.2625"/>
      <parent link="base_link_top"/>
      <child link="base_iiwa"/>
  </joint>

  <link name="base_iiwa">
      <inertial>
        <origin xyz="-0.1 0 0.07" rpy="0 0 0"/>
        <mass value="5"/>
        <inertia ixx="0.05"  ixy="0"  ixz="0" iyy="0.06" iyz="0" izz="0.03" />
      </inertial>
      <visual>
        <origin rpy="0.0 0 0" xyz="0 0 0"/>
        <geometry>
          <mesh filename="package://kmr_bringup/meshes/lbr_iiwa_14_r820/visual/base_link.dae"/>
        </geometry>
      </visual>
      <collision>
        <origin rpy="0 0 0" xyz="0 0 0"/>
        <geometry>
          <mesh filename="package://kmr_bringup/meshes/lbr_iiwa_14_r820/collision/base_link.stl"/>
        </geometry>
      </collision>
  </link>
  <link name="link_1">
      <inertial>
        <origin xyz="0 -0.03 0.12" rpy="0 0 0"/>
        <mass value="4"/>
        <inertia ixx="0.1"  ixy="0"  ixz="0" iyy="0.09" iyz="0" izz="0.02" />
      </inertial>
      <visual>
        <origin rpy="0 0 0" xyz="0 0 0"/>
        <geometry>
          <mesh filename="package://kmr_bringup/meshes/lbr_iiwa_14_r820/visual/link_1.dae"/>
        </geometry>
      </visual>
      <collision>
        <origin rpy="0 0 0" xyz="0 0 0"/>
        <geometry>
          <mesh filename="package://kmr_bringup/meshes/lbr_iiwa_14_r820/collision/link_1.stl"/>
        </geometry>
      </collision>
  </link>
  <link name="link_2">
      <inertial>
        <origin xyz="0.0003 0.059 0.042" rpy="0 0 0"/>
        <mass value="4"/>
        <inertia ixx="0.05"  ixy="0"  ixz="0" iyy="0.018" iyz="0" izz="0.044" />
      </inertial>
      <visual>
        <origin rpy="0 0 0" xyz="0 0 0"/>
        <geometry>
          <mesh filename="package://kmr_bringup/meshes/lbr_iiwa_14_r820/visual/link_2.dae"/>
        </geometry>
      </visual>
      <collision>
        <origin rpy="0 0 0" xyz="0 0 0"/>
        <geometry>
          <mesh filename="package://kmr_bringup/meshes/lbr_iiwa_14_r820/collision/link_2.stl"/>
        </geometry>
      </collision>
  </link>
  <link name="link_3">
      <inertial>
        <origin xyz="0 0.03 0.13" rpy="0 0 0"/>
        <mass value="3"/>
        <inertia ixx="0.08"  ixy="0"  ixz="0" iyy="0.075" iyz="0" izz="0.01" />
      </inertial>
      <visual>
        <origin rpy="0 0 0" xyz="0 0 0"/>
        <geometry>
          <mesh filename="package://kmr_bringup/meshes/lbr_iiwa_14_r820/visual/link_3.dae"/>
        </geometry>
      </visual>
      <collision>
        <origin rpy="0 0 0" xyz="0 0 0"/>
        <geometry>
          <mesh filename="package://kmr_bringup/meshes/lbr_iiwa_14_r820/collision/link_3.stl"/>
        </geometry>
      </collision>
  </link>
  <link name="link_4">
      <inertial>
        <origin xyz="0 0.067 0.034" rpy="0 0 0"/>
        <mass value="2.7"/>
        <inertia ixx="0.03"  ixy="0"  ixz="0" iyy="0.01" iyz="0" izz="0.029" />
      </inertial>
      <visual>
        <origin rpy="0 0 0" xyz="0 0 0"/>
        <geometry>
          <mesh filename="package://kmr_bringup/meshes/lbr_iiwa_14_r820/visual/link_4.dae"/>
        </geometry>
      </visual>
      <collision>
        <origin rpy="0 0 0" xyz="0 0 0"/>
        <geometry>
          <mesh filename="package://kmr_bringup/meshes/lbr_iiwa_14_r820/collision/link_4.stl"/>
        </geometry>
      </collision>
  </link>
  <link name="link_5">
      <inertial>
        <origin xyz="0.0001 0.021 0.076" rpy="0 0 0"/>
        <mass value="1.7"/>
        <inertia ixx="0.02"  ixy="0"  ixz="0" iyy="0.018" iyz="0" izz="0.005" />
      </inertial>
      <visual>
        <origin rpy="0 0 0" xyz="0 0 0"/>
        <geometry>
          <mesh filename="package://kmr_bringup/meshes/lbr_iiwa_14_r820/visual/link_5.dae"/>
        </geometry>
      </visual>
      <collision>
        <origin rpy="0 0 0" xyz="0 0 0"/>
        <geometry>
          <mesh filename="package://kmr_bringup/meshes/lbr_iiwa_14_r820/collision/link_5.stl"/>
        </geometry>
      </collision>
  </link>
  <link name="link_6">
      <inertial>
        <origin xyz="0 0.0006 0.0004" rpy="0 0 0"/>
        <mass value="1.8"/>
        <inertia ixx="0.005"  ixy="0"  ixz="0" iyy="0.0036" iyz="0" izz="0.0047" />
      </inertial>
      <visual>
        <origin rpy="0 0 0" xyz="0 0 0"/>
        <geometry>
          <mesh filename="package://kmr_bringup/meshes/lbr_iiwa_14_r820/visual/link_6.dae"/>
        </geometry>
      </visual>
      <collision>
        <origin rpy="0 0 0" xyz="0 0 0"/>
        <geometry>
          <mesh filename="package://kmr_bringup/meshes/lbr_iiwa_14_r820/collision/link_6.stl"/>
        </geometry>
      </collision>
  </link>
  <link name="link_7">
      <inertial>
        <origin xyz="0 0 0.02" rpy="0 0 0"/>
        <mass value="0.3"/>
        <inertia ixx="0.001"  ixy="0"  ixz="0" iyy="0.001" iyz="0" izz="0.001" />
      </inertial>
      <visual>
        <origin rpy="0 0 0" xyz="0 0 0"/>
        <geometry>
          <mesh filename="package://kmr_bringup/meshes/lbr_iiwa_14_r820/visual/link_7.dae"/>
        </geometry>
      </visual>
      <collision>
        <origin rpy="0 0 0" xyz="0 0 0"/>
        <geometry>
          <mesh filename="package://kmr_bringup/meshes/lbr_iiwa_14_r820/collision/link_7.stl"/>
        </geometry>
      </collision>
  </link>


  <joint name="joint_a1" type="revolute">
      <origin rpy="0 0 0" xyz="0 0 0"/>
      <parent link="base_iiwa"/>
      <child link="link_1"/>
      <axis xyz="0 0 1"/>
      <limit effort="0" lower="-2.9668" upper="2.9668" velocity="1.4834"/>
  </joint>
  <joint name="joint_a2" type="revolute">
      <origin rpy="0 0 0" xyz="-0.00043624 0 0.36"/>
      <parent link="link_1"/>
      <child link="link_2"/>
      <axis xyz="0 1 0"/>
      <limit effort="0" lower="-2.0942" upper="2.0942" velocity="1.4834"/>
  </joint>
  <joint name="joint_a3" type="revolute">
      <origin rpy="0 0 0" xyz="0 0 0"/>
      <parent link="link_2"/>
      <child link="link_3"/>
      <axis xyz="0 0 1"/>
      <limit effort="0" lower="-2.9668" upper="2.9668" velocity="1.7452"/>
  </joint>
  <joint name="joint_a4" type="revolute">
      <origin rpy="0 0 0" xyz="0.00043624 0 0.42"/>
      <parent link="link_3"/>
      <child link="link_4"/>
      <axis xyz="0 -1 0"/>
      <limit effort="0" lower="-2.0942" upper="2.0942" velocity="1.3089"/>
  </joint>
  <joint name="joint_a5" type="revolute">
      <origin rpy="0 0 0" xyz="0 0 0"/>
      <parent link="link_4"/>
      <child link="link_5"/>
      <axis xyz="0 0 1"/>
      <limit effort="0" lower="-2.9668" upper="2.9668" velocity="2.2688"/>
  </joint>
  <joint name="joint_a6" type="revolute">
      <origin rpy="0 0 0" xyz="0 0 0.4"/>
      <parent link="link_5"/>
      <child link="link_6"/>
      <axis xyz="0 1 0"/>
      <limit effort="0" lower="-2.0942" upper="2.0942" velocity="2.356"/>
  </joint>
  <joint name="joint_a7" type="revolute">
      <origin rpy="0 0 0" xyz="0 0 0"/>
      <parent link="link_6"/>
      <child link="link_7"/>
      <axis xyz="0 0 1"/>
      <limit effort="0" lower="-3.0541" upper="3.0541" velocity="2.356"/>
  </joint>

  <joint name="joint_a7-adapter" type="fixed">
      <origin rpy="0 0 -0.785398" xyz="0 0 0.1365"/>
      <parent link="link_7"/>
      <child link="adapter"/>
      <axis xyz="0 0 0"/>
  </joint>

  <link name="adapter">
    <visual>
      <origin xyz="0 0 0" rpy="0 0 0" />
      <geometry>
        <cylinder length="0.035" radius="0.0375" />
      </geometry>
      <material name="aluminum"/>
    </visual>
  </link>

  <joint name="joint_adapter-feste1" type="fixed">
      <origin rpy="0 0 0" xyz="-0.0425 0 0.0125"/>
      <parent link="adapter"/>
      <child link="kamerafeste1"/>
      <axis xyz="0 0 0"/>
  </joint>
  
  <link name="kamerafeste1">
    <visual>
      <origin xyz="0 0 0" rpy="0 0 0" />
      <geometry>
        <box size="0.01 0.015 0.01"/>
      </geometry>
      <material name="aluminum"/>
    </visual>
  </link>

  <joint name="joint_adapter-feste2" type="fixed">
      <origin rpy="0 0 0" xyz="-0.01 0 0.005"/>
      <parent link="kamerafeste1"/>
      <child link="kamerafeste2"/>
      <axis xyz="0 0 0"/>
  </joint>

  <link name="kamerafeste2">
    <visual>
      <origin xyz="0 0 0" rpy="0 0 0" />
      <geometry>
        <box size="0.01 0.015 0.02"/>
      </geometry>
      <material name="aluminum"/>
    </visual>
  </link>

  <!-- Manipulator camera, with origin at bottom screw mount -->
    <joint name="d435_manipulator_joint" type="fixed">
      <origin xyz="-0.005 0.0 0.005" rpy="0 -1.570796 0"/>
      <parent link="kamerafeste2"/>
      <child link="d435_manipulator_link" />
    </joint>

    <link name="d435_manipulator_link">
      <visual>
      <origin xyz="0.0149 0.0 0.0125" rpy="1.570796 0 1.570796 "/>
        <geometry>
	        <mesh filename="package://kmr_bringup/meshes/sensors/visual/d435.dae" />
        </geometry>
        <material name="aluminum"/>
      </visual>
      <collision>
        <origin xyz="0.0149 0.0 0.0125" rpy="3.1415 1.570796 0 "/>
        <geometry>
        <box size="0.02505 0.090 0.025"/>
        </geometry>
      </collision>
      <inertial>
        <!-- The following are not reliable values, and should not be used for modeling -->
        <mass value="0.564" />
        <origin xyz="0 0 0" />
        <inertia ixx="0.003881243" ixy="0.0" ixz="0.0" iyy="0.000498940" iyz="0.0" izz="0.003879257" />
      </inertial>
    </link>
    <!--  -->

    <joint name="d435_manipulator_depth_joint" type="fixed">
      <origin xyz="0.0149 -0.0075 0.0125" rpy="0 0 0"/>
      <parent link="d435_manipulator_link"/>
      <child link="d435_manipulator_depth_frame" />
    </joint>

    <link name="d435_manipulator_depth_frame"/>

    <joint name="d435_manipulator_depth_optical_joint" type="fixed">
      <origin xyz="0 0 0" rpy="-1.570796 0 -1.570796" />
      <parent link= "d435_manipulator_depth_frame" />
      <child link="d435_manipulator_depth_optical_frame" />
    </joint>

    <link name="d435_manipulator_depth_optical_frame"/>


  <joint name="joint_adapter-gripperadapter" type="fixed">
      <origin rpy="0 0 0" xyz="0 0 0.0255"/>
      <parent link="adapter"/>
      <child link="gripper-adapter"/>
      <axis xyz="0 0 0"/>
  </joint>

  <link name="gripper-adapter">
    <visual>
      <origin xyz="0 0 0" rpy="0 0 0" />
      <geometry>
        <cylinder length="0.016" radius="0.0375" />
      </geometry>
      <material name="Black"/>
    </visual>
  </link>

  <joint name="joint_gripperadapter-gripper" type="fixed">
      <origin rpy="0 0 0" xyz="0 0 0.008"/>
      <parent link="gripper-adapter"/>
      <child link="gripper_base_link"/>
      <axis xyz="0 0 0"/>
  </joint>


  <link name="gripper_base_link">
    <inertial>
      <origin
        xyz="0.00021987 -2.3546E-10 0.030163"
        rpy="0 0 0" />
      <mass value="0.30915" />
      <inertia
        ixx="0.00028972"
        ixy="-5.7879E-10"
        ixz="-1.8543E-06"
        iyy="0.00030737"
        iyz="1.682E-12"
        izz="0.00019914" />
    </inertial>
    <visual>
      <origin xyz="0 0 0" rpy="0 0 0" />
      <geometry>
        <mesh filename="package://kmr_bringup/meshes/gripper/visual/robotiq_arg2f_85_base_link.dae" scale="0.001 0.001 0.001"/>
      </geometry>
      <material name="">
        <color rgba="0.1 0.1 0.1 1" />
      </material>
    </visual>
    <collision>
      <origin xyz="0 0 0" rpy="0 0 0" />
      <geometry>
        <mesh filename="package://kmr_bringup/meshes/gripper/collision/robotiq_arg2f_base_link.stl" />
      </geometry>
    </collision>
  </link>

  <joint name="right_outer_knuckle_joint" type="fixed">
      <origin xyz="0 0.0306011 0.054904" rpy="0 0 0"/>
      <parent link="gripper_base_link" />
      <child link="right_outer_knuckle" />
      <axis xyz="1 0 0" />
      <limit lower="0" upper="0.81" velocity="2.0" effort="1000" />
    </joint>

    <link name="left_outer_knuckle">
      <inertial>
        <origin
          xyz="0.0178331863169983 3.68915177224286E-11 0.0021442477325704"
          rpy="0 0 0" />
        <mass
          value="0.00684838849434396" />
        <inertia
          ixx="2.66832029033166E-07"
          ixy="1.66142314639824E-15"
          ixz="1.45945633322873E-07"
          iyy="1.3889233257419E-06"
          iyz="2.82951161241588E-15"
          izz="1.26603336914415E-06" />
      </inertial>
      <visual>
        <origin xyz="0 0 0" rpy="0 0 0" />
        <geometry>
          <mesh filename="package://kmr_bringup/meshes/gripper/visual/robotiq_arg2f_85_outer_knuckle.dae" scale="0.001 0.001 0.001"/>
        </geometry>
        <material name="">
          <color rgba="0.792156862745098 0.819607843137255 0.933333333333333 1" />
        </material>
      </visual>
      <collision>
        <origin xyz="0 0 0" rpy="0 0 0" />
        <geometry>
          <mesh filename="package://kmr_bringup/meshes/gripper/collision/robotiq_arg2f_85_outer_knuckle.dae" scale="0.001 0.001 0.001"/>
        </geometry>
      </collision>
    </link>
    <link name="right_outer_knuckle">
      <inertial>
        <origin
          xyz="0.0178097074051638 3.60493211424024E-11 0.00233123458346721"
          rpy="0 0 0" />
        <mass
          value="0.00684838849401352" />
        <inertia
          ixx="2.70004361573169E-07"
          ixy="1.59579467624491E-15"
          ixz="1.56396493788199E-07"
          iyy="1.38892332558312E-06"
          iyz="2.82357800318817E-15"
          izz="1.26286103637978E-06" />
      </inertial>
      <visual>
        <origin xyz="0 0 0" rpy="0 0 0" />
        <geometry>
          <mesh filename="package://kmr_bringup/meshes/gripper/visual/robotiq_arg2f_85_outer_knuckle.dae" scale="0.001 0.001 0.001"/>
        </geometry>
        <material name="">
          <color rgba="0.792156862745098 0.819607843137255 0.933333333333333 1" />
        </material>
      </visual>
      <collision>
        <origin xyz="0 0 0" rpy="0 0 0" />
        <geometry>
          <mesh filename="package://kmr_bringup/meshes/gripper/collision/robotiq_arg2f_85_outer_knuckle.dae" scale="0.001 0.001 0.001"/>
        </geometry>
      </collision>
    </link>

    <link name="left_outer_finger">
      <inertial>
        <origin
          xyz="0.00131451599174296 2.88942057994543E-15 0.0215404163180413"
          rpy="0 0 0" />
        <mass
          value="0.0273093985570947" />
        <inertia
          ixx="8.51629628283022E-06"
          ixy="2.58174336207405E-19"
          ixz="3.83829504344079E-07"
          iyy="6.9133328065108E-06"
          iyz="-7.58589926143789E-19"
          izz="2.25006832221981E-06" />
      </inertial>
      <visual>
        <origin xyz="0 0 0" rpy="0 0 0" />
        <geometry>
          <mesh filename="package://kmr_bringup/meshes/gripper/visual/robotiq_arg2f_85_outer_finger.dae" scale="0.001 0.001 0.001"/>
        </geometry>
        <material name="">
          <color rgba="0.1 0.1 0.1 1" />
        </material>
      </visual>
      <collision>
        <origin xyz="0 0 0" rpy="0 0 0" />
        <geometry>
          <mesh filename="package://kmr_bringup/meshes/gripper/collision/robotiq_arg2f_85_outer_finger.dae" scale="0.001 0.001 0.001"/>
        </geometry>
      </collision>
    </link>

    <link name="right_outer_finger">
      <inertial>
        <origin
          xyz="0.00108844269639009 -2.611488350845E-15 0.0215530225245502"
          rpy="0 0 0" />
        <mass
          value="0.0273093985570947" />
        <inertia
          ixx="8.52366028592721E-06"
          ixy="3.41683380899422E-19"
          ixz="3.18003675694284E-07"
          iyy="6.91333280651081E-06"
          iyz="7.37726682706417E-19"
          izz="2.24270431912283E-06" />
      </inertial>
      <visual>
        <origin xyz="0 0 0" rpy="0 0 0" />
        <geometry>
          <mesh filename="package://kmr_bringup/meshes/gripper/visual/robotiq_arg2f_85_outer_finger.dae" scale="0.001 0.001 0.001"/>
        </geometry>
        <material name="">
          <color rgba="0.1 0.1 0.1 1" />
        </material>
      </visual>
      <collision>
        <origin xyz="0 0 0" rpy="0 0 0" />
        <geometry>
          <mesh filename="package://kmr_bringup/meshes/gripper/collision/robotiq_arg2f_85_outer_finger.dae" scale="0.001 0.001 0.001"/>
        </geometry>
      </collision>
    </link>

    <link name="left_inner_knuckle">
      <inertial>
        <origin
          xyz="0.017097546626628 -3.93808524389535E-10 0.0224918438201868"
          rpy="0 0 0" />
        <mass
          value="0.0110930853895903" />
        <inertia
          ixx="4.23392770691541E-06"
          ixy="5.748978936968E-15"
          ixz="1.78855677119788E-06"
          iyy="3.96548790524392E-06"
          iyz="1.05464666369669E-14"
          izz="3.24068002883007E-06" />
      </inertial>
      <visual>
        <origin xyz="0 0 0" rpy="0 0 0" />
        <geometry>
          <mesh filename="package://kmr_bringup/meshes/gripper/visual/robotiq_arg2f_85_inner_knuckle.dae" scale="0.001 0.001 0.001"/>
        </geometry>
        <material name="">
          <color rgba="0.1 0.1 0.1 1" />
        </material>
      </visual>
      <collision>
        <origin xyz="0 0 0" rpy="0 0 0" />
        <geometry>
          <mesh filename="package://kmr_bringup/meshes/gripper/collision/robotiq_arg2f_85_inner_knuckle.dae" scale="0.001 0.001 0.001"/>
        </geometry>
      </collision>
    </link>

    <link name="right_inner_knuckle">
      <inertial>
        <origin
          xyz="0.0168606186773776 3.93808471820465E-10 0.0226699950793434"
          rpy="0 0 0" />
        <mass
          value="0.0110930853895903" />
        <inertia
          ixx="4.27134775939882E-06"
          ixy="-8.53568456728898E-15"
          ixz="1.77774229944246E-06"
          iyy="3.96548790524392E-06"
          iyz="-8.45108024914164E-15"
          izz="3.20325997634666E-06" />
      </inertial>
      <visual>
        <origin xyz="0 0 0" rpy="0 0 0" />
        <geometry>
          <mesh filename="package://kmr_bringup/meshes/gripper/visual/robotiq_arg2f_85_inner_knuckle.dae" scale="0.001 0.001 0.001"/>
        </geometry>
        <material name="">
          <color rgba="0.1 0.1 0.1 1" />
        </material>
      </visual>
      <collision>
        <origin xyz="0 0 0" rpy="0 0 0" />
        <geometry>
          <mesh filename="package://kmr_bringup/meshes/gripper/collision/robotiq_arg2f_85_inner_knuckle.dae" scale="0.001 0.001 0.001"/>
        </geometry>
      </collision>
    </link>

    <link name="left_inner_finger">
      <inertial>
        <origin
          xyz="0.0060275613594574 -6.29183141465421E-15 0.00669925693133241"
          rpy="0 0 0" />
        <mass
          value="0.00724255346165745" />
        <inertia
          ixx="1.47824274053603E-06"
          ixy="-3.94884463570303E-19"
          ixz="-3.45268847648622E-07"
          iyy="1.70064480838395E-06"
          iyz="3.5059838910097E-19"
          izz="4.77151336838364E-07" />
      </inertial>
      <visual>
        <origin xyz="0 0 0" rpy="0 0 0" />
        <geometry>
          <mesh filename="package://kmr_bringup/meshes/gripper/visual/robotiq_arg2f_85_inner_finger.dae" scale="0.001 0.001 0.001"/>
        </geometry>
        <material name="">
          <color rgba="0.1 0.1 0.1 1" />
        </material>
      </visual>
      <collision>
        <origin xyz="0 0 0" rpy="0 0 0" />
        <geometry>
          <mesh filename="package://kmr_bringup/meshes/gripper/collision/robotiq_arg2f_85_inner_finger.dae" scale="0.001 0.001 0.001" />
        </geometry>
      </collision>
    </link>

    <link name="right_inner_finger">
      <inertial>
        <origin
          xyz="0.00602756228812038 -6.47284509480176E-15 0.00669925609578108"
          rpy="0 0 0" />
        <mass
          value="0.00724255346165744" />
        <inertia
          ixx="1.47824283625957E-06"
          ixy="-3.95952064019123E-19"
          ixz="-3.45268708875543E-07"
          iyy="1.70064480838394E-06"
          iyz="3.55286507960029E-19"
          izz="4.77151241114822E-07" />
      </inertial>
      <visual>
        <origin xyz="0 0 0" rpy="0 0 0" />
        <geometry>
          <mesh filename="package://kmr_bringup/meshes/gripper/visual/robotiq_arg2f_85_inner_finger.dae" scale="0.001 0.001 0.001"/>
        </geometry>
        <material name="">
          <color rgba="0.1 0.1 0.1 1" />
        </material>
      </visual>
      <collision>
        <origin xyz="0 0 0" rpy="0 0 0" />
        <geometry>
          <mesh filename="package://kmr_bringup/meshes/gripper/collision/robotiq_arg2f_85_inner_finger.dae" scale="0.001 0.001 0.001" />
        </geometry>
      </collision>
    </link>

   <!-- Finger pad link, the default are the "big pads" with rubber-->
    <link name="left_inner_finger_pad">
      <visual>
        <origin xyz="0 0 0" rpy="0 0 0" />
        <geometry>
          <box size="0.022 0.00635 0.0375"/>
        </geometry>
        <material name="">
          <color rgba="0.9 0.9 0.9 1" />
        </material>
      </visual>
      <collision>
        <origin xyz="0 0 0" rpy="0 0 0" />
        <geometry>
           <box size="0.022 0.00635 0.0375"/>
        </geometry>
        <material name="">
          <color rgba="0.9 0.0 0.0 1" />
        </material>
      </collision>
      <inertial>
          <mass value="0.019555" />
          <origin xyz="0.0 0.0 0.0" />
          <inertia ixx = "0.000002" ixy = "0.000000" ixz = "0.000000"
                    iyx = "0.000000" iyy = "0.000005" iyz = "0.000000"
                    izx = "0.000000" izy = "0.000000" izz = "0.000006" />
      </inertial>
    </link>
    <link name="right_inner_finger_pad">
      <visual>
        <origin xyz="0 0 0" rpy="0 0 0" />
        <geometry>
          <box size="0.022 0.00635 0.0375"/>
        </geometry>
        <material name="">
          <color rgba="0.9 0.9 0.9 1" />
        </material>
      </visual>
      <collision>
        <origin xyz="0 0 0" rpy="0 0 0" />
        <geometry>
           <box size="0.022 0.00635 0.0375"/>
        </geometry>
        <material name="">
          <color rgba="0.9 0.0 0.0 1" />
        </material>
      </collision>
      <inertial>
        <mass value="0.019555" />
        <origin xyz="0.0 0.0 0.0" />
        <inertia ixx = "0.000002" ixy = "0.000000" ixz = "0.000000"
                  iyx = "0.000000" iyy = "0.000005" iyz = "0.000000"
                  izx = "0.000000" izy = "0.000000" izz = "0.000006" />
      </inertial>
    </link>

    <joint name="gripper_middle_point" type="fixed">
      <origin xyz="0 0.0 0.144" rpy="0 0 0"/>
      <parent link="gripper_base_link" />
      <child link="gripper_middle_point" />
    </joint>
    <link name="gripper_middle_point"/>

    <joint name="left_outer_finger_joint" type="fixed">
      <origin xyz="0 0.0315 -0.0041" rpy="0 0 0"/>
      <parent link="left_outer_knuckle" />
      <child link="left_outer_finger" />
      <axis xyz="1 0 0" />
    </joint>

    <joint name="right_outer_finger_joint" type="fixed">
      <origin xyz="0 0.0315 -0.0041" rpy="0 0 0"/>
      <parent link="right_outer_knuckle" />
      <child link="right_outer_finger" />
      <axis xyz="1 0 0" />
    </joint>

    <joint name="left_inner_knuckle_joint" type="fixed">
      <origin xyz="0 -0.0127 0.06142" rpy="0 0 3.1415"/>
      <parent link="gripper_base_link" />
      <child link="left_inner_knuckle" />
      <axis xyz="1 0 0" />
      <limit lower="0" upper="0.8757" velocity="2.0" effort="1000" />
    </joint>

    <joint name="right_inner_knuckle_joint" type="fixed">
      <origin xyz="0 0.0127 0.06142" rpy="0 0 0"/>
      <parent link="gripper_base_link" />
      <child link="right_inner_knuckle" />
      <axis xyz="1 0 0" />
      <limit lower="0" upper="0.8757" velocity="2.0" effort="1000" />
    </joint>

    <joint name="left_inner_finger_joint" type="fixed">
      <origin xyz="0 0.0061 0.0471" rpy="0 0 0"/>
      <parent link="left_outer_finger" />
      <child link="left_inner_finger" />
      <axis xyz="1 0 0" />
      <limit lower="0" upper="0.8757" velocity="2.0" effort="1000" />
    </joint>

    <joint name="right_inner_finger_joint" type="fixed">
      <origin xyz="0 0.0061 0.0471" rpy="0 0 0"/>
      <parent link="right_outer_finger" />
      <child link="right_inner_finger" />
      <axis xyz="1 0 0" />
      <limit lower="0" upper="0.8757" velocity="2.0" effort="1000" />
    </joint>


    <joint name="left_inner_finger_pad_joint" type="fixed">
      <origin xyz="0 -0.0220203446692936 0.03242" rpy="0 0 0"/>
      <parent link="left_inner_finger" />
      <child link="left_inner_finger_pad" />
      <axis xyz="0 0 1" />
    </joint>

    <joint name="right_inner_finger_pad_joint" type="fixed">
      <origin xyz="0 -0.0220203446692936 0.03242" rpy="0 0 0"/>
      <parent link="right_inner_finger" />
      <child link="right_inner_finger_pad" />
      <axis xyz="0 0 1" />
    </joint>

    <joint name="finger_joint" type="fixed">
      <origin xyz="0 -0.0306011 0.054904" rpy="0 0 3.1415"/>
      <parent link="gripper_base_link" />
      <child link="left_outer_knuckle" />
      <axis xyz="1 0 0" />
      <limit lower="0" upper="0.8" velocity="2.0" effort="1000" />
    </joint>

    
    <!-- camera body, with origin at bottom screw mount -->
    <joint name="d435_base_front_joint" type="fixed">
      <origin xyz="0.52 0.0 0.2625" rpy="0 0 0"/>
      <parent link="base_link_top"/>
      <child link="d435_base_front_link" />
    </joint>

    <link name="d435_base_front_link">
      <visual>
      <origin xyz="0.0149 0.0 0.0125" rpy="1.570796 0 1.570796"/>
        <geometry>
	        <mesh filename="package://kmr_bringup/meshes/sensors/visual/d435.dae" />
        </geometry>
        <material name="aluminum"/>
      </visual>
      <collision>
        <origin xyz="0.0 0.0 0.0125" rpy="0 0 0"/>
        <geometry>
        <box size="0.02505 0.090 0.025"/>
        </geometry>
      </collision>
      <inertial>
        <!-- The following are not reliable values, and should not be used for modeling -->
        <mass value="0.564" />
        <origin xyz="0 0 0" />
        <inertia ixx="0.003881243" ixy="0.0" ixz="0.0" iyy="0.000498940" iyz="0.0" izz="0.003879257" />
      </inertial>
    </link>
   
    <!-- camera depth joints and links -->
    <joint name="d435_base_front_depth_joint" type="fixed">
      <origin xyz="0.0149 -0.0075 0.0125" rpy="0 0 0"/>
      <parent link="d435_base_front_link"/>
      <child link="d435_base_front_depth_frame" />
    </joint>

    <link name="d435_base_front_depth_frame"/>

    <joint name="d435_base_front_depth_optical_joint" type="fixed">
      <origin xyz="0 0 0" rpy="-1.570796 0 -1.570796" />
      <parent link= "d435_base_front_depth_frame" />
      <child link="d435_base_front_depth_optical_frame" />
    </joint>

    <link name="d435_base_front_depth_optical_frame"/>



    <joint name="metall_plate_left_joint" type="fixed">
      <origin xyz="-0.08 0.28 0.2675" rpy="0 0 0"/>
      <parent link="base_link_top"/>
      <child link="metall_plate_left_link" />
    </joint>

    <link name="metall_plate_left_link">
      <visual>
        <origin xyz="0.0 0.0 0.0" rpy="0.0 0 0.0 "/>
          <geometry>
            <box size="0.2 0.04 0.01"/>
          </geometry>
          <material name="aluminum"/>
      </visual>
      <collision>
        <origin xyz="0.0 0.0 0.0" rpy="0.0 0 0.0 "/>
          <geometry>
            <box size="0.2 0.04 0.01"/>
          </geometry>
      </collision>
    </link>


  <!-- D435 camera on the base - left side, with origin at bottom screw mount -->
    <joint name="d435_base_left_joint" type="fixed">
      <origin xyz="0.0 0.0 0.005" rpy="0 0.0 1.570796"/>
      <parent link="metall_plate_left_link"/>
      <child link="d435_base_left_link" />
    </joint>

    <link name="d435_base_left_link">
      <visual>
      <origin xyz="0.0149 0.0 0.0125" rpy="1.570796 0 1.570796 "/>
        <geometry>
	        <mesh filename="package://kmr_bringup/meshes/sensors/visual/d435.dae" />
        </geometry>
        <material name="aluminum"/>
      </visual>
      <collision>
        <origin xyz="0.0149 0.0 0.0125" rpy="3.1415 1.570796 0 "/>
        <geometry>
        <box size="0.02505 0.090 0.025"/>
        </geometry>
      </collision>
      <inertial>
        <!-- The following are not reliable values, and should not be used for modeling -->
        <mass value="0.564" />
        <origin xyz="0 0 0" />
        <inertia ixx="0.003881243" ixy="0.0" ixz="0.0" iyy="0.000498940" iyz="0.0" izz="0.003879257" />
      </inertial>
    </link>
    <!--  -->

    <joint name="metall_plate_right_joint" type="fixed">
      <origin xyz="-0.08 -0.28 0.2675" rpy="0 0 0"/>
      <parent link="base_link_top"/>
      <child link="metall_plate_right_link" />
    </joint>

    <link name="metall_plate_right_link">
      <visual>
        <origin xyz="0.0 0.0 0.0" rpy="0.0 0 0.0 "/>
          <geometry>
            <box size="0.2 0.04 0.01"/>
          </geometry>
          <material name="aluminum"/>
      </visual>
      <collision>
        <origin xyz="0.0 0.0 0.0" rpy="0.0 0 0.0 "/>
          <geometry>
            <box size="0.2 0.04 0.01"/>
          </geometry>
      </collision>
    </link>


  <!-- D435 camera on the base - right side, with origin at bottom screw mount -->
    <joint name="d435_base_right_joint" type="fixed">
      <origin xyz="0.0 0.0 0.005" rpy="0 0 -1.570796"/>
      <parent link="metall_plate_right_link"/>
      <child link="d435_base_right_link" />
    </joint>

    <link name="d435_base_right_link">
      <visual>
      <origin xyz="0.0149 0.0 0.0125" rpy="1.570796 0 1.570796 "/>
        <geometry>
	        <mesh filename="package://kmr_bringup/meshes/sensors/visual/d435.dae" />
        </geometry>
        <material name="aluminum"/>
      </visual>
      <collision>
        <origin xyz="0.0149 0.0 0.0125" rpy="3.1415 1.570796 0 "/>
        <geometry>
          <box size="0.02505 0.090 0.025"/>
        </geometry>
      </collision>
      <inertial>
        <!-- The following are not reliable values, and should not be used for modeling -->
        <mass value="0.564" />
        <origin xyz="0 0 0" />
        <inertia ixx="0.003881243" ixy="0.0" ixz="0.0" iyy="0.000498940" iyz="0.0" izz="0.003879257" />
      </inertial>
    </link>
    <!--  -->
</robot>